<?xml version="1.0"?>
<robot xmlns:xacro="http://ros.org/wiki/xacro" name="turtlebot3">
  
  <!-- Properties -->
  <xacro:property name="wheel_radius" value="0.033"/>
  <xacro:property name="wheel_width" value="0.08"/>
  <xacro:property name="robot_radius" value="0.18"/>
  <xacro:property name="robot_height" value="0.1"/>
  <xacro:property name="lidar_height" value="0.1"/>
  <xacro:property name="camera_height" value="0.2"/>

  <!-- Base Link -->
  <link name="base_link">
    <visual>
      <geometry>
        <cylinder radius="${robot_radius}" length="${robot_height}"/>
      </geometry>
      <material name="green"/>
    </visual>
  </link>

  <!-- LIDAR -->
  <link name="lidar_link">
    <visual>
      <geometry>
        <cylinder radius="0.05" length="0.1"/>
      </geometry>
      <material name="blue"/>
    </visual>
  </link>
  <joint name="lidar_joint" type="fixed">
    <parent link="base_link"/>
    <child link="lidar_link"/>
    <origin xyz="0 0 ${lidar_height}" rpy="0 0 0"/>
  </joint>

  <!-- Camera -->
  <link name="camera_link">
    <visual>
      <geometry>
        <box size="0.05 0.05 0.1"/>
      </geometry>
      <material name="red"/>
    </visual>
  </link>
  <joint name="camera_joint" type="fixed">
    <parent link="base_link"/>
    <child link="camera_link"/>
    <origin xyz="0 0 ${camera_height}" rpy="0 0 0"/>
  </joint>

  <!-- Wheels -->
  <link name="wheel_left">
    <visual>
      <geometry>
        <cylinder radius="${wheel_radius}" length="${wheel_width}"/>
      </geometry>
      <material name="black"/>
    </visual>
  </link>
  <link name="wheel_right">
    <visual>
      <geometry>
        <cylinder radius="${wheel_radius}" length="${wheel_width}"/>
      </geometry>
      <material name="black"/>
    </visual>
  </link>
  
  <!-- Left Wheel Joint -->
  <joint name="wheel_left_joint" type="continuous">
    <parent link="base_link"/>
    <child link="wheel_left"/>
    <origin xyz="${robot_radius}" rpy="0 0 0"/>
    <axis xyz="0 1 0"/>
  </joint>
  
  <!-- Right Wheel Joint -->
  <joint name="wheel_right_joint" type="continuous">
    <parent link="base_link"/>
    <child link="wheel_right"/>
    <origin xyz="-${robot_radius}" rpy="0 0 0"/>
    <axis xyz="0 1 0"/>
  </joint>

</robot>