<?xml version="1.0"?>
<robot xmlns:xacro="http://ros.org/wiki/xacro" name="turtlebot3">
  
  <!-- Properties -->
  <xacro:property name="wheel_radius" value="0.033"/>
  <xacro:property name="wheel_width" value="0.08"/>
  <xacro:property name="robot_radius" value="0.18"/>
  <xacro:property name="robot_height" value="0.1"/>
  <xacro:property name="lidar_height" value="0.1"/>
  <xacro:property name="camera_height" value="0.2"/>

  <!-- Base Link -->
  <link name="base_link">
    <visual>
      <geometry>
        <cylinder radius="${robot_radius}" length="${robot_height}"/>
      </geometry>
      <material name="green"/>
    </visual>
  </link>

  <!-- LIDAR -->
  <link name="lidar_link">
    <visual>
      <geometry>
        <cylinder radius="0.05" length="0.1"/>
      </geometry>
      <material name="blue"/>
    </visual>
  </link>
  <joint name="lidar_joint" type="fixed">
    <parent link="base_link"/>
    <child link="lidar_link"/>
    <origin xyz="0 0 ${lidar_height}" rpy="0 0 0"/>
  </joint>

  <!-- Camera -->
  <link name="camera_link">
    <visual>
      <geometry>
        <box size="0.05 0.05 0.1"/>
      </geometry>
      <material name="red"/>
    </visual>
  </link>
  <joint name="camera_joint" type="fixed">
    <parent link="base_link"/>
    <child link="camera_link"/>
    <origin xyz="0 0 ${camera_height}" rpy="0 0 0"/>
  </joint>

  <!-- Wheels -->
  <link name="wheel_left">
    <visual>
      <geometry>
        <cylinder radius="${wheel_radius}" length="${wheel_width}"/>
      </geometry>
      <material name="black"/>
    </visual>
  </link>
  <link name="wheel_right">
    <visual>
      <geometry>
        <cylinder radius="${wheel_radius}" length="${wheel_width}"/>
      </geometry>
      <material name="black"/>
    </visual>
  </link>
  
  <!-- Left Wheel Joint -->
  <joint name="wheel_left_joint" type="continuous">
    <parent link="base_link"/>
    <child link="wheel_left"/>
    <origin xyz="${robot_radius}" rpy="0 0 0"/>
    <axis xyz="0 1 0"/>
  </joint>
  
  <!-- Right Wheel Joint -->
  <joint name="wheel_right_joint" type="continuous">
    <parent link="base_link"/>
    <child link="wheel_right"/>
    <origin xyz="-${robot_radius}" rpy="0 0 0"/>
    <axis xyz="0 1 0"/>
  </joint>

</robot>

<!-- 
<gazebo>
  <!-- LIDAR Sensor Plugin -->
  <sensor type="ray" name="lidar_sensor">
    <pose>0 0 0 0 0 0</pose>
    <update_rate>10</update_rate>
    <ray>
      <scan>
        <horizontal>
          <samples>360</samples>
          <resolution>1</resolution>
          <min_angle>-1.5708</min_angle>
          <max_angle>1.5708</max_angle>
        </horizontal>
      </scan>
      <range>
        <min>0.1</min>
        <max>10.0</max>
        <resolution>0.01</resolution>
      </range>
    </ray>
    <plugin name="gazebo_ros_laser" filename="libgazebo_ros_laser.so">
      <topicName>/scan</topicName>
      <frameName>lidar_link</frameName>
    </plugin>
  </sensor>
  
  <!-- Depth Camera Sensor Plugin -->
  <sensor type="depth" name="depth_camera">
    <pose>0 0 0 0 0 0</pose>
    <update_rate>30</update_rate>
    <camera>
      <horizontal_fov>1.047</horizontal_fov>
      <image>
        <width>640</width>
        <height>480</height>
        <format>R8G8B8</format>
      </image>
      <clip>
        <near>0.1</near>
        <far>10.0</far>
      </clip>
    </camera>
    <plugin name="gazebo_ros_depth_camera" filename="libgazebo_ros_depth_camera.so">
      <cameraName>depth_camera</cameraName>
      <topicName>/camera/depth</topicName>
    </plugin>
  </sensor>
</gazebo> -->
